Workbook

Sheet Work Component  Split
C2: Work Allocation
D3: Seniors Review | E3: Accountants Work | F3: Bookkeeper's Work
C4: Management Accounts | D4: 0.1 | E4: 0.4 | F4: 0.5
C5: Payroll | D5: 0.1 | E5: 0.9 | F5: 0
C6: Once Off Work | D6: 0.1 | E6: 0.9 | F6: 0
C9: Client | D9: Payroll (Cost Incl) | E9: Management accounts (Cost Incl) | F9: Total Amount (Cost Excl) | G9: P: Reviewer | H9: P: Accountant | I9: MA: Bookkeeper | J9: MA: Accountant | K9: MA: Reviewer | L9: % total
C10: Maxopani Holdings | D10: =7948.8*100/115 -> 6912 | E10: =18600/1.15 -> 16173.913 | F10: 23085.91 | G10: =(D10*$D$5)/F10 -> 0.02994034 | H10: =(D10*$E$5)/F10 -> 0.26946306 | I10: =(E10*$F$4)/F10 -> 0.35029836 | J10: =(E10*$E$4)/F10 -> 0.28023869 | K10: =(E10*$D$4)/F10 -> 0.070059673 | L10: =K10+J10+I10+H10+G10 -> 1.0000001 | N10: 1.15
C11: Sinet Africa | D11: 0 | E11: =4968/1.15 -> 4320 | F11: 4320 | G11: =(D11*$D$5)/F11 -> 0 | H11: =(D11*$E$5)/F11 -> 0 | I11: =(E11*$F$4)/F11 -> 0.5 | J11: =(E11*$E$4)/F11 -> 0.4 | K11: =(E11*$D$4)/F11 -> 0.1 | L11: =K11+J11+I11+H11+G11 -> 1
C12: Innovateher | D12: 0 | E12: =28444.5108/1.15 -> 24734.357 | F12: 24734.36 | G12: =(D12*$D$5)/F12 -> 0 | H12: =(D12*$E$5)/F12 -> 0 | I12: =(E12*$F$4)/F12 -> 0.49999994 | J12: =(E12*$E$4)/F12 -> 0.39999996 | K12: =(E12*$D$4)/F12 -> 0.099999989 | L12: =K12+J12+I12+H12+G12 -> 0.99999989
C13: Khulio Electric | D13: 0 | E13: =14904/1.15 -> 12960 | F13: 12960 | G13: =(D13*$D$5)/F13 -> 0 | H13: =(D13*$E$5)/F13 -> 0 | I13: =(E13*$F$4)/F13 -> 0.5 | J13: =(E13*$E$4)/F13 -> 0.4 | K13: =(E13*$D$4)/F13 -> 0.1 | L13: =K13+J13+I13+H13+G13 -> 1
C14: Hambo Lwethu | D14: 0 | E14: =5302.098/1.15 -> 4610.52 | F14: 4610.52 | G14: =(D14*$D$5)/F14 -> 0 | H14: =(D14*$E$5)/F14 -> 0 | I14: =(E14*$F$4)/F14 -> 0.5 | J14: =(E14*$E$4)/F14 -> 0.4 | K14: =(E14*$D$4)/F14 -> 0.1 | L14: =K14+J14+I14+H14+G14 -> 1
C15: Spade | D15: 0 | E15: 0 | F15: =E15+D15 -> 0 | G15: =(D15*$D$5)/F15 -> #DIV/0! | H15: =(D15*$E$5)/F15 -> #DIV/0! | I15: =(E15*$F$4)/F15 -> #DIV/0! | J15: =(E15*$E$4)/F15 -> #DIV/0! | K15: =(E15*$D$4)/F15 -> #DIV/0! | L15: =K15+J15+I15+H15+G15 -> #DIV/0!
C16: Makhubela Incorporated | D16: =500/1.15 -> 434.78261 | E16: =1851.77/1.15 -> 1610.2348 | F16: 2045.02 | G16: =(D16*$D$5)/F16 -> 0.021260555 | H16: =(D16*$E$5)/F16 -> 0.191345 | I16: =(E16*$F$4)/F16 -> 0.39369659 | J16: =(E16*$E$4)/F16 -> 0.31495727 | K16: =(E16*$D$4)/F16 -> 0.078739317 | L16: =K16+J16+I16+H16+G16 -> 0.99999872
C17: Destiny Finance (Pty) Ltd | D17: =3585.14/1.15 -> 3117.513 | E17: =6613.65/1.15 -> 5751 | F17: 8868.51 | G17: =(D17*$D$5)/F17 -> 0.035152613 | H17: =(D17*$E$5)/F17 -> 0.31637352 | I17: =(E17*$F$4)/F17 -> 0.3242371 | J17: =(E17*$E$4)/F17 -> 0.25938968 | K17: =(E17*$D$4)/F17 -> 0.064847421 | L17: =K17+J17+I17+H17+G17 -> 1.0000003
C18: DR WW NGWATA PRACTICE INC | D18: =460/1.15 -> 400 | E18: =3189.02/1.15 -> 2773.0609 | F18: 3173.06 | G18: =(D18*$D$5)/F18 -> 0.012606128 | H18: =(D18*$E$5)/F18 -> 0.11345515 | I18: =(E18*$F$4)/F18 -> 0.4369695 | J18: =(E18*$E$4)/F18 -> 0.3495756 | K18: =(E18*$D$4)/F18 -> 0.0873939 | L18: =K18+J18+I18+H18+G18 -> 1.0000003
C19: Bixa Consulting | D19: =500/1.15 -> 434.78261 | E19: =2794.5/1.15 -> 2430 | F19: 2864.78 | G19: =(D19*$D$5)/F19 -> 0.015176824 | H19: =(D19*$E$5)/F19 -> 0.13659141 | I19: =(E19*$F$4)/F19 -> 0.42411634 | J19: =(E19*$E$4)/F19 -> 0.33929307 | K19: =(E19*$D$4)/F19 -> 0.084823267 | L19: =K19+J19+I19+H19+G19 -> 1.0000009
C20: Mvundlane | D20: 0 | E20: =3105/1.15 -> 2700 | F20: 2700 | G20: =(D20*$D$5)/F20 -> 0 | H20: =(D20*$E$5)/F20 -> 0 | I20: =(E20*$F$4)/F20 -> 0.5 | J20: =(E20*$E$4)/F20 -> 0.4 | K20: =(E20*$D$4)/F20 -> 0.1 | L20: =K20+J20+I20+H20+G20 -> 1
C21: Solid Re Global | D21: 0 | E21: =2916/1.15 -> 2535.6522 | F21: 2535.65 | G21: =(D21*$D$5)/F21 -> 0 | H21: =(D21*$E$5)/F21 -> 0 | I21: =(E21*$F$4)/F21 -> 0.50000043 | J21: =(E21*$E$4)/F21 -> 0.40000034 | K21: =(E21*$D$4)/F21 -> 0.10000009 | L21: =K21+J21+I21+H21+G21 -> 1.0000009
C22: Drs Koranteng | D22: 0 | E22: =3050.14/1.15 -> 2652.2957 | F22: 2652.29 | G22: =(D22*$D$5)/F22 -> 0 | H22: =(D22*$E$5)/F22 -> 0 | I22: =(E22*$F$4)/F22 -> 0.50000107 | J22: =(E22*$E$4)/F22 -> 0.40000085 | K22: =(E22*$D$4)/F22 -> 0.10000021 | L22: =K22+J22+I22+H22+G22 -> 1.0000021
C23: Destiny Portfolio | D23: 0 | E23: =4448.84/1.15 -> 3868.5565 | F23: 3868.56 | G23: =(D23*$D$5)/F23 -> 0 | H23: =(D23*$E$5)/F23 -> 0 | I23: =(E23*$F$4)/F23 -> 0.49999955 | J23: =(E23*$E$4)/F23 -> 0.39999964 | K23: =(E23*$D$4)/F23 -> 0.09999991 | L23: =K23+J23+I23+H23+G23 -> 0.9999991
C24: Giant Bee Logistics Pty Ltd | D24: =1252.42/1.15 -> 1089.0609 | E24: =5410.15/1.15 -> 4704.4783 | F24: 5793.54 | G24: =(D24*$D$5)/F24 -> 0.018797848 | H24: =(D24*$E$5)/F24 -> 0.16918064 | I24: =(E24*$F$4)/F24 -> 0.40601068 | J24: =(E24*$E$4)/F24 -> 0.32480855 | K24: =(E24*$D$4)/F24 -> 0.081202137 | L24: =K24+J24+I24+H24+G24 -> 0.99999985
C25: Pono Vision Radiology | D25: 0 | E25: =2052/1.15 -> 1784.3478 | F25: 1784.35 | G25: =(D25*$D$5)/F25 -> 0 | H25: =(D25*$E$5)/F25 -> 0 | I25: =(E25*$F$4)/F25 -> 0.49999939 | J25: =(E25*$E$4)/F25 -> 0.39999951 | K25: =(E25*$D$4)/F25 -> 0.099999878 | L25: =K25+J25+I25+H25+G25 -> 0.99999878
C26: Achri | D26: 0 | E26: =16121.16/1.15 -> 14018.4 | F26: 14018.4 | G26: =(D26*$D$5)/F26 -> 0 | H26: =(D26*$E$5)/F26 -> 0 | I26: =(E26*$F$4)/F26 -> 0.5 | J26: =(E26*$E$4)/F26 -> 0.4 | K26: =(E26*$D$4)/F26 -> 0.1 | L26: =K26+J26+I26+H26+G26 -> 1
C27: Astra Matellite | D27: =2190.0375/1.15 -> 1904.3804 | E27: =3937.5/1.15 -> 3423.913 | F27: 5328.2935 | G27: =(D27*$D$5)/F27 -> 0.035740907 | H27: =(D27*$E$5)/F27 -> 0.32166817 | I27: =(E27*$F$4)/F27 -> 0.32129546 | J27: =(E27*$E$4)/F27 -> 0.25703637 | K27: =(E27*$D$4)/F27 -> 0.064259093 | L27: =K27+J27+I27+H27+G27 -> 1
C28: Advocate Maputla | D28: 0 | E28: =28959.12/1.15 -> 25181.843 | F28: 25181.84 | G28: =(D28*$D$5)/F28 -> 0 | H28: =(D28*$E$5)/F28 -> 0 | I28: =(E28*$F$4)/F28 -> 0.50000007 | J28: =(E28*$E$4)/F28 -> 0.40000006 | K28: =(E28*$D$4)/F28 -> 0.10000001 | L28: =K28+J28+I28+H28+G28 -> 1.0000001
C29: CREATIVE VALLEY NURSERY SCHOOL | D29: =1075/1.15 -> 934.78261 | E29: =2368.7748/1.15 -> 2059.8042 | F29: 2994.59 | G29: =(D29*$D$5)/F29 -> 0.031215713 | H29: =(D29*$E$5)/F29 -> 0.28094141 | I29: =(E29*$F$4)/F29 -> 0.3439209 | J29: =(E29*$E$4)/F29 -> 0.27513672 | K29: =(E29*$D$4)/F29 -> 0.06878418 | L29: =K29+J29+I29+H29+G29 -> 0.99999893
C30: Depesh Cara | D30: =540/1.15 -> 469.56522 | E30: 3478.2608 | F30: =E30+D30 -> 3947.826 | G30: =(D30*$D$5)/F30 -> 0.011894273 | H30: =(D30*$E$5)/F30 -> 0.10704846 | I30: =(E30*$F$4)/F30 -> 0.44052863 | J30: =(E30*$E$4)/F30 -> 0.35242291 | K30: =(E30*$D$4)/F30 -> 0.088105727 | L30: =K30+J30+I30+H30+G30 -> 1
C31: Dr A.S Bajomo | D31: =550/1.15 -> 478.26087 | E31: =4089.852/1.15 -> 3556.393 | F31: 4034.65 | G31: =(D31*$D$5)/F31 -> 0.011853838 | H31: =(D31*$E$5)/F31 -> 0.10668454 | I31: =(E31*$F$4)/F31 -> 0.4407313 | J31: =(E31*$E$4)/F31 -> 0.35258504 | K31: =(E31*$D$4)/F31 -> 0.088146259 | L31: =K31+J31+I31+H31+G31 -> 1.000001
C32: Katomax Investments | D32: 0 | E32: =2916.0216/1.15 -> 2535.671 | F32: 2535.67 | G32: =(D32*$D$5)/F32 -> 0 | H32: =(D32*$E$5)/F32 -> 0 | I32: =(E32*$F$4)/F32 -> 0.50000019 | J32: =(E32*$E$4)/F32 -> 0.40000015 | K32: =(E32*$D$4)/F32 -> 0.10000004 | L32: =K32+J32+I32+H32+G32 -> 1.0000004
C33: New Orlscade | D33: 0 | E33: =8694/1.15 -> 7560 | F33: 7560 | G33: =(D33*$D$5)/F33 -> 0 | H33: =(D33*$E$5)/F33 -> 0 | I33: =(E33*$F$4)/F33 -> 0.5 | J33: =(E33*$E$4)/F33 -> 0.4 | K33: =(E33*$D$4)/F33 -> 0.1 | L33: =K33+J33+I33+H33+G33 -> 1
C34: Rentals Proper team Fourways | D34: 0 | E34: =3936.6/1.15 -> 3423.1304 | F34: 3423.13 | G34: =(D34*$D$5)/F34 -> 0 | H34: =(D34*$E$5)/F34 -> 0 | I34: =(E34*$F$4)/F34 -> 0.50000006 | J34: =(E34*$E$4)/F34 -> 0.40000005 | K34: =(E34*$D$4)/F34 -> 0.10000001 | L34: =K34+J34+I34+H34+G34 -> 1.0000001
C35: TMM TECH | D35: 0 | E35: =4082.4/1.15 -> 3549.913 | F35: 3549.91 | G35: =(D35*$D$5)/F35 -> 0 | H35: =(D35*$E$5)/F35 -> 0 | I35: =(E35*$F$4)/F35 -> 0.50000043 | J35: =(E35*$E$4)/F35 -> 0.40000034 | K35: =(E35*$D$4)/F35 -> 0.10000009 | L35: =K35+J35+I35+H35+G35 -> 1.0000009
C36: Mectech Motors | D36: =1251.936/1.15 -> 1088.64 | E36: =6095.736/1.15 -> 5300.64 | F36: 6389.28 | G36: =(D36*$D$5)/F36 -> 0.01703854 | H36: =(D36*$E$5)/F36 -> 0.15334686 | I36: =(E36*$F$4)/F36 -> 0.4148073 | J36: =(E36*$E$4)/F36 -> 0.33184584 | K36: =(E36*$D$4)/F36 -> 0.08296146 | L36: =K36+J36+I36+H36+G36 -> 1
C37: Blue Hill | D37: =700/1.15 -> 608.69565 | E37: =3780/1.15 -> 3286.9565 | F37: 3895.65 | G37: =(D37*$D$5)/F37 -> 0.015625009 | H37: =(D37*$E$5)/F37 -> 0.14062508 | I37: =(E37*$F$4)/F37 -> 0.42187524 | J37: =(E37*$E$4)/F37 -> 0.33750019 | K37: =(E37*$D$4)/F37 -> 0.084375047 | L37: =K37+J37+I37+H37+G37 -> 1.0000006
C38: Chemstrat | D38: 0 | E38: =16146/1.15 -> 14040 | F38: 14040 | G38: =(D38*$D$5)/F38 -> 0 | H38: =(D38*$E$5)/F38 -> 0 | I38: =(E38*$F$4)/F38 -> 0.5 | J38: =(E38*$E$4)/F38 -> 0.4 | K38: =(E38*$D$4)/F38 -> 0.1 | L38: =K38+J38+I38+H38+G38 -> 1
C39: R Protections | D39: 0 | E39: =9315/1.15 -> 8100 | F39: 8100 | G39: =(D39*$D$5)/F39 -> 0 | H39: =(D39*$E$5)/F39 -> 0 | I39: =(E39*$F$4)/F39 -> 0.5 | J39: =(E39*$E$4)/F39 -> 0.4 | K39: =(E39*$D$4)/F39 -> 0.1 | L39: =K39+J39+I39+H39+G39 -> 1
C40: Fitness Reenvisioned | D40: 0 | E40: =1807.92/1.15 -> 1572.1043 | F40: 1572.1 | G40: =(D40*$D$5)/F40 -> 0 | H40: =(D40*$E$5)/F40 -> 0 | I40: =(E40*$F$4)/F40 -> 0.50000138 | J40: =(E40*$E$4)/F40 -> 0.40000111 | K40: =(E40*$D$4)/F40 -> 0.10000028 | L40: =K40+J40+I40+H40+G40 -> 1.0000028
C41: Luk Capital | D41: 0 | E41: =2985.984/1.15 -> 2596.5078 | F41: 2596.51 | G41: =(D41*$D$5)/F41 -> 0 | H41: =(D41*$E$5)/F41 -> 0 | I41: =(E41*$F$4)/F41 -> 0.49999958 | J41: =(E41*$E$4)/F41 -> 0.39999967 | K41: =(E41*$D$4)/F41 -> 0.099999916 | L41: =K41+J41+I41+H41+G41 -> 0.99999916
C42: Moja Legal Consulting and Investment (Pty) Ltd | D42: 0 | E42: =2332.8/1.15 -> 2028.5217 | F42: 2028.52 | G42: =(D42*$D$5)/F42 -> 0 | H42: =(D42*$E$5)/F42 -> 0 | I42: =(E42*$F$4)/F42 -> 0.50000043 | J42: =(E42*$E$4)/F42 -> 0.40000034 | K42: =(E42*$D$4)/F42 -> 0.10000009 | L42: =K42+J42+I42+H42+G42 -> 1.0000009
C43: Vera Step | D43: 0 | E43: =3384.45/1.15 -> 2943 | F43: 2943 | G43: =(D43*$D$5)/F43 -> 0 | H43: =(D43*$E$5)/F43 -> 0 | I43: =(E43*$F$4)/F43 -> 0.5 | J43: =(E43*$E$4)/F43 -> 0.4 | K43: =(E43*$D$4)/F43 -> 0.1 | L43: =K43+J43+I43+H43+G43 -> 1
...

Sheet Star Jan - Dec '26
F3: Workflow Scheduling
B8: "A business is a commercial profitable enterprise that runs without you"
C10: Workflow Dashboard
B11: Senior Client Manager In Charge : | G11: Mollen Mukuze
B12: Team Name: | G12: Star Bongowongo
B14: Team Member: | D14: Star | G14: Role: | J14: Senior Auditor
C15: Analysis: | E15: Fees: | G15: Analysis: | K15: Hours:
C16: Annual Fee Budget | E16: =85000*12 -> 1020000 | G16: Annual Budgeted Hours | K16: =E16/C32 -> 1457.1429
C17: Scheduled Work and Jobs | E17: =+I88+I174+I243+I313+I383+I453+I523+I593+I663+I733+I803+I873 -> 38502.92 | G17: Scheduled Hours | K17: =+J88+J174+J243+J313+J383+J453+J523+J593+J663+J733+J803+J873 -> 55.004171
C18: Over (Under) Scheduled Work | E18: =E17-E16 -> -981497.08 | G18: Over (Under) Scheduled Work | K18: =K17-K16 -> -1402.1387
B20: Remaining Hours to Fill:
D21: January | E21: =J32 -> 114.01106 | F21: Apr | G21: =+J251 -> 121.6 | H21: July | I21: =+J461 -> 134.4 | J21: Oct | K21: =+J671 -> 147.2
D22: Feb | E22: =+J97 -> 93.384773 | F22: May | G22: =+J321 -> 140.8 | H22: Aug | I22: =J531 -> 134.4 | J22: Nov | K22: =+J741 -> 128
D23: Mar | E23: =+J182 -> 134.4 | F23: June | G23: =+J391 -> 128 | H23: Sept | I23: =+J601 -> 134.4 | J23: Dec | K23: =+J811 -> 128
B25: Total Productivity Hours To Fill : | G25: =SUM(E21:E23)+SUM(G21:G23)+SUM(I21:I23)+SUM(K21:K23) -> 1538.5958
C30: Workflow Schedule for | E30: January | J30: 2026
C31: Charge Rate: | D31: Working Days in Month | F31: KPI % | G31: Hours per Day | H31: Monthly Budgeted Hours | I31: Total Scheduled Fees | J31: Hours Left
C32: 700 | D32: 21 | F32: 0.8 | G32: 8 | H32: =D32*G32*F32 -> 134.4 | I32: =I88 -> 14272.261 | J32: =H32-J88 -> 114.01106
C33: Entity Group \ Job Name | D33: Notes | F33: Estimated Fees for Job | G33: Team Members Job Completion % | H33: Pricing or Efficiency Override | I33: Budgeted WIP | J33: Job Budgeted Hrs | K33: Submission Date to client | L33: Accountants commnent on Due Date
C35: Monthly Recurring Work
C36: Management Accounts:
B37: 1 | C37: Innovateher | F37: ='Work Component Split'!F12 -> 24734.36 | G37: ='Work Component Split'!K12 -> 0.099999989 | H37: 1 | I37: =J37*$C$32 -> 2473.4357 | J37: =(F37*G37*H37)/$C$32 -> 3.5334796
B38: =B37+1 -> 2 | C38: Makhubela Incorporated | F38: ='Work Component Split'!F16 -> 2045.02 | G38: ='Work Component Split'!K16 -> 0.078739317 | H38: 1 | I38: =J38*$C$32 -> 161.02348 | J38: =(F38*G38*H38)/$C$32 -> 0.23003354
B39: =B38+1 -> 3 | C39: Destiny Finance (Pty) Ltd | F39: ='Work Component Split'!F17 -> 8868.51 | G39: ='Work Component Split'!K17 -> 0.064847421 | H39: 1 | I39: =J39*$C$32 -> 575.1 | J39: =(F39*G39*H39)/$C$32 -> 0.82157143
B40: =B39+1 -> 4 | C40: DR WW NGWATA PRACTICE INC | F40: ='Work Component Split'!F18 -> 3173.06 | G40: ='Work Component Split'!K18 -> 0.0873939 | H40: 1 | I40: =J40*$C$32 -> 277.30609 | J40: =(F40*G40*H40)/$C$32 -> 0.39615155
B41: =B40+1 -> 5 | C41: Bixa Consulting | F41: ='Work Component Split'!F19 -> 2864.78 | G41: ='Work Component Split'!K19 -> 0.084823267 | H41: 1 | I41: =J41*$C$32 -> 243 | J41: =(F41*G41*H41)/$C$32 -> 0.34714286
B42: =B41+1 -> 6 | C42: Mvundlane | F42: ='Work Component Split'!F20 -> 2700 | G42: ='Work Component Split'!K20 -> 0.1 | H42: 1 | I42: =J42*$C$32 -> 270 | J42: =(F42*G42*H42)/$C$32 -> 0.38571429
B43: =B42+1 -> 7 | C43: Solid Re Global | F43: ='Work Component Split'!F21 -> 2535.65 | G43: ='Work Component Split'!K21 -> 0.10000009 | H43: 1 | I43: =J43*$C$32 -> 253.56522 | J43: =(F43*G43*H43)/$C$32 -> 0.36223602
B44: =B43+1 -> 8 | C44: Drs Koranteng | F44: ='Work Component Split'!F22 -> 2652.29 | G44: ='Work Component Split'!K22 -> 0.10000021 | H44: 1 | I44: =J44*$C$32 -> 265.22957 | J44: =(F44*G44*H44)/$C$32 -> 0.37889938
B45: =B44+1 -> 9 | C45: Destiny Portfolio | F45: ='Work Component Split'!F23 -> 3868.56 | G45: ='Work Component Split'!K23 -> 0.09999991 | H45: 1 | I45: =J45*$C$32 -> 386.85565 | J45: =(F45*G45*H45)/$C$32 -> 0.55265093
B46: =B45+1 -> 10 | C46: Giant Bee Logistics Pty Ltd | F46: ='Work Component Split'!F24 -> 5793.54 | G46: ='Work Component Split'!K24 -> 0.081202137 | H46: 1 | I46: =J46*$C$32 -> 470.44783 | J46: =(F46*G46*H46)/$C$32 -> 0.67206832
B47: =B46+1 -> 11 | C47: Pono Vision Radiology | F47: ='Work Component Split'!F25 -> 1784.35 | G47: ='Work Component Split'!K25 -> 0.099999878 | H47: 1 | I47: =J47*$C$32 -> 178.43478 | J47: =(F47*G47*H47)/$C$32 -> 0.25490683
B48: =B47+1 -> 12 | C48: Achri | F48: ='Work Component Split'!F26 -> 14018.4 | G48: ='Work Component Split'!K26 -> 0.1 | H48: 1 | I48: =J48*$C$32 -> 1401.84 | J48: =(F48*G48*H48)/$C$32 -> 2.0026286
B49: =B48+1 -> 13 | C49: Astra Matellite | F49: ='Work Component Split'!F27 -> 5328.2935 | G49: ='Work Component Split'!K27 -> 0.064259093 | H49: 1 | I49: =J49*$C$32 -> 342.3913 | J49: =(F49*G49*H49)/$C$32 -> 0.48913043
B50: =B49+1 -> 14 | C50: CREATIVE VALLEY NURSERY SCHOOL | F50: ='Work Component Split'!F29 -> 2994.59 | G50: ='Work Component Split'!K29 -> 0.06878418 | H50: 1 | I50: =J50*$C$32 -> 205.98042 | J50: =(F50*G50*H50)/$C$32 -> 0.29425774
B51: =B50+1 -> 15 | C51: Katomax Investments | F51: ='Work Component Split'!F31 -> 4034.65 | G51: ='Work Component Split'!K31 -> 0.088146259 | H51: 1 | I51: =J51*$C$32 -> 355.6393 | J51: =(F51*G51*H51)/$C$32 -> 0.50805615
B52: =B51+1 -> 16 | C52: Mectech Motors | F52: ='Work Component Split'!F35 -> 3549.91 | G52: ='Work Component Split'!K35 -> 0.10000009 | H52: 1 | I52: =J52*$C$32 -> 354.9913 | J52: =(F52*G52*H52)/$C$32 -> 0.50713043
B53: =B52+1 -> 17 | C53: Chemstrat | F53: ='Work Component Split'!F37 -> 3895.65 | G53: ='Work Component Split'!K37 -> 0.084375047 | H53: 1 | I53: =J53*$C$32 -> 328.69565 | J53: =(F53*G53*H53)/$C$32 -> 0.46956522
B54: =B53+1 -> 18 | C54: Fitness Reenvisioned | F54: ='Work Component Split'!F39 -> 8100 | G54: ='Work Component Split'!K39 -> 0.1 | H54: 1 | I54: =J54*$C$32 -> 810 | J54: =(F54*G54*H54)/$C$32 -> 1.1571429
B55: =B54+1 -> 19 | C55: Luk Capital | F55: ='Work Component Split'!F40 -> 1572.1 | G55: ='Work Component Split'!K40 -> 0.10000028 | H55: 1 | I55: =J55*$C$32 -> 157.21043 | J55: =(F55*G55*H55)/$C$32 -> 0.22458634
...

Sheet Kenneth Jan - Dec '26
F3: Workflow Scheduling
B8: "A business is a commercial profitable enterprise that runs without you"
C10: Workflow Dashboard
B11: Senior Client Manager In Charge : | G11: Star Bongowongo
B12: Team Name: | G12: Kenneth Mashava
B14: Team Member: | D14: Kenneth | G14: Role: | J14: Accountant
C15: Analysis: | E15: Fees: | G15: Analysis: | K15: Hours:
C16: Annual Fee Budget | E16: =54720*12 -> 656640 | G16: Annual Budgeted Hours | K16: =E16/C32 -> 1459.2
C17: Scheduled Work and Jobs | E17: =+I67+I113+I182+I252+I322+I392+I462+I532+I602+I672+I742+I812 -> 45252.148 | G17: Scheduled Hours | K17: =+J67+J113+J182+J252+J322+J392+J462+J532+J602+J672+J742+J812 -> 100.56033
C18: Over (Under) Scheduled Work | E18: =E17-E16 -> -611387.85 | G18: Over (Under) Scheduled Work | K18: =K17-K16 -> -1358.6397
B20: Remaining Hours to Fill:
D21: January | E21: =J32 -> 58.501637 | F21: Apr | G21: =+J190 -> 121.6 | H21: July | I21: =+J400 -> 134.4 | J21: Oct | K21: =+J610 -> 147.2
D22: Feb | E22: =+J76 -> 103.33803 | F22: May | G22: =+J260 -> 140.8 | H22: Aug | I22: =J470 -> 134.4 | J22: Nov | K22: =+J680 -> 128
D23: Mar | E23: =+J121 -> 134.4 | F23: June | G23: =+J330 -> 128 | H23: Sept | I23: =+J540 -> 134.4 | J23: Dec | K23: =+J750 -> 128
B25: Total Productivity Hours To Fill : | G25: =SUM(E21:E23)+SUM(G21:G23)+SUM(I21:I23)+SUM(K21:K23) -> 1493.0397
C30: Workflow Schedule for | E30: January | J30: 2026
C31: Charge Rate: | D31: Working Days in Month | F31: KPI % | G31: Hours per Day | H31: Monthly Budgeted Hours | I31: Total Scheduled Fees | J31: Hours Left
C32: 450 | D32: 21 | F32: 0.8 | G32: 8 | H32: =D32*G32*F32 -> 134.4 | I32: =I67 -> 34154.263 | J32: =H32-J67 -> 58.501637
C33: Entity Group \ Job Name | D33: Notes | F33: Estimated Fees for Job | G33: Team Members Job Completion % | H33: Pricing or Efficiency Override | I33: Budgeted WIP | J33: Job Budgeted Hrs | K33: Submission Date to client | L33: Accountants commnent on Due Date
C35: Monthly Recurring Work
C36: Management Accounts:
B37: 1 | C37: Makhubela Incorporated | F37: ='Work Component Split'!F16 -> 2045.02 | G37: ='Work Component Split'!J16 -> 0.31495727 | H37: 1 | I37: =J37*$C$32 -> 644.09391 | J37: =(F37*G37*H37)/$C$32 -> 1.4313198
B38: 2 | C38: Destiny Finance (Pty) Ltd | F38: ='Work Component Split'!F17 -> 8868.51 | G38: ='Work Component Split'!J17 -> 0.25938968 | H38: 1 | I38: =J38*$C$32 -> 2300.4 | J38: =(F38*G38*H38)/$C$32 -> 5.112
B39: 3 | C39: DR WW NGWATA PRACTICE INC | F39: ='Work Component Split'!F18 -> 3173.06 | G39: ='Work Component Split'!J18 -> 0.3495756 | H39: 1 | I39: =J39*$C$32 -> 1109.2243 | J39: =(F39*G39*H39)/$C$32 -> 2.464943
B40: 4 | C40: Bixa Consulting | F40: ='Work Component Split'!F19 -> 2864.78 | G40: ='Work Component Split'!J19 -> 0.33929307 | H40: 1 | I40: =J40*$C$32 -> 972 | J40: =(F40*G40*H40)/$C$32 -> 2.16
B41: 5 | C41: Mvundlane | F41: ='Work Component Split'!F20 -> 2700 | G41: ='Work Component Split'!J20 -> 0.4 | H41: 1 | I41: =J41*$C$32 -> 1080 | J41: =(F41*G41*H41)/$C$32 -> 2.4
B42: 6 | C42: Solid Re Global | F42: ='Work Component Split'!F21 -> 2535.65 | G42: ='Work Component Split'!J21 -> 0.40000034 | H42: 1 | I42: =J42*$C$32 -> 1014.2609 | J42: =(F42*G42*H42)/$C$32 -> 2.253913
B43: 7 | C43: Drs Koranteng | F43: ='Work Component Split'!F22 -> 2652.29 | G43: ='Work Component Split'!J22 -> 0.40000085 | H43: 1 | I43: =J43*$C$32 -> 1060.9183 | J43: =(F43*G43*H43)/$C$32 -> 2.3575961
B44: 8 | C44: Destiny Portfolio | F44: ='Work Component Split'!F23 -> 3868.56 | G44: ='Work Component Split'!J23 -> 0.39999964 | H44: 1 | I44: =J44*$C$32 -> 1547.4226 | J44: =(F44*G44*H44)/$C$32 -> 3.4387169
B45: 9 | C45: Astra Matellite | F45: ='Work Component Split'!F27 -> 5328.2935 | G45: ='Work Component Split'!J27 -> 0.25703637 | H45: 1 | I45: =J45*$C$32 -> 1369.5652 | J45: =(F45*G45*H45)/$C$32 -> 3.0434783
C48: Once Off work:
B49: 1 | C49: Siyaphila Trading | F49: 41391.31 | G49: 0.4 | H49: 1 | I49: =J49*$C$32 -> 16556.524 | J49: =(F49*G49*H49)/$C$32 -> 36.792276
B50: 2 | C50: Astra Matellite | F50: 7222.06 | G50: 0.9 | H50: 1 | I50: =J50*$C$32 -> 6499.854 | J50: =(F50*G50*H50)/$C$32 -> 14.44412
B51: 4 | H51: 1 | I51: =J51*$C$32 -> 0 | J51: =(F51*G51*H51)/$C$32 -> 0
B52: 5 | H52: 1 | I52: =J52*$C$32 -> 0 | J52: =(F52*G52*H52)/$C$32 -> 0
B53: 6 | H53: 1 | I53: =J53*$C$32 -> 0 | J53: =(F53*G53*H53)/$C$32 -> 0
B54: 7 | H54: 1 | I54: =J54*$C$32 -> 0 | J54: =(F54*G54*H54)/$C$32 -> 0
B55: 8 | H55: 1 | I55: =J55*$C$32 -> 0 | J55: =(F55*G55*H55)/$C$32 -> 0
B56: 9 | H56: 1 | I56: =J56*$C$32 -> 0 | J56: =(F56*G56*H56)/$C$32 -> 0
B57: 10 | H57: 1 | I57: =J57*$C$32 -> 0 | J57: =(F57*G57*H57)/$C$32 -> 0
...

Sheet Tatenda Jan - Dec '26
F3: Workflow Scheduling
B8: "A business is a commercial profitable enterprise that runs without you"
C10: Workflow Dashboard
B11: Senior Client Manager In Charge : | G11: Star Bongowongo
B12: Team Name: | G12: Tatenda Chasakara
B14: Team Member: | D14: Tatenda | G14: Role: | J14: Accountant
C15: Analysis: | E15: Fees: | G15: Analysis: | K15: Hours:
C16: Annual Fee Budget | E16: =54720*12 -> 656640 | G16: Annual Budgeted Hours | K16: =E16/C32 -> 1459.2
C17: Scheduled Work and Jobs | E17: =+I56+I102+I171+I241+I311+I381+I451+I521+I591+I661+I731+I801 -> 35013.261 | G17: Scheduled Hours | K17: =+J56+J102+J171+J241+J311+J381+J451+J521+J591+J661+J731+J801 -> 77.807247
C18: Over (Under) Scheduled Work | E18: =E17-E16 -> -621626.74 | G18: Over (Under) Scheduled Work | K18: =K17-K16 -> -1381.3928
B20: Remaining Hours to Fill:
D21: January | E21: =J32 -> 112.4139 | F21: Apr | G21: =+J179 -> 121.6 | H21: July | I21: =+J389 -> 134.4 | J21: Oct | K21: =+J599 -> 147.2
D22: Feb | E22: =+J65 -> 72.178851 | F22: May | G22: =+J249 -> 140.8 | H22: Aug | I22: =J459 -> 134.4 | J22: Nov | K22: =+J669 -> 128
D23: Mar | E23: =+J110 -> 134.4 | F23: June | G23: =+J319 -> 128 | H23: Sept | I23: =+J529 -> 134.4 | J23: Dec | K23: =+J739 -> 128
B25: Total Productivity Hours To Fill : | G25: =SUM(E21:E23)+SUM(G21:G23)+SUM(I21:I23)+SUM(K21:K23) -> 1515.7928
C30: Workflow Schedule for | E30: January | J30: 2026
C31: Charge Rate: | D31: Working Days in Month | F31: KPI % | G31: Hours per Day | H31: Monthly Budgeted Hours | I31: Total Scheduled Fees | J31: Hours Left
C32: 450 | D32: 21 | F32: 0.8 | G32: 8 | H32: =D32*G32*F32 -> 134.4 | I32: =I56 -> 9893.744 | J32: =H32-J56 -> 112.4139
C33: Entity Group \ Job Name | D33: Notes | F33: Estimated Fees for Job | G33: Team Members Job Completion % | H33: Pricing or Efficiency Override | I33: Budgeted WIP | J33: Job Budgeted Hrs | K33: Submission Date to client | L33: Accountants commnent on Due Date
C35: Monthly Recurring Work
C36: Management Accounts:
B37: 1 | C37: Innovateher | F37: ='Work Component Split'!F12 -> 24734.36 | G37: ='Work Component Split'!J11 -> 0.4 | H37: 1 | I37: =J37*$C$32 -> 9893.744 | J37: =(F37*G37*H37)/$C$32 -> 21.986098
C40: Once Off Client:
B41: 1 | C41: Aquity Innovations NPC | D41: Audit | H41: 1 | I41: =J41*$C$32 -> 0 | J41: =(F41*G41*H41)/$C$32 -> 0
B42: 2 | C42: Hambo Lwethu Travel | D42: Bank Reconciliation | H42: 1 | I42: =J42*$C$32 -> 0 | J42: =(F42*G42*H42)/$C$32 -> 0
B43: 4 | C43: Implantcast SA (Pty) Ltd | D43: Audit | H43: 1 | I43: =J43*$C$32 -> 0 | J43: =(F43*G43*H43)/$C$32 -> 0
B44: 7 | C44: Rutendo Addeline Gavhera | D44: Tax submission | H44: 1 | I44: =J44*$C$32 -> 0 | J44: =(F44*G44*H44)/$C$32 -> 0
B45: 8 | C45: SA SELLO | D45: Tax submission | H45: 1 | I45: =J45*$C$32 -> 0 | J45: =(F45*G45*H45)/$C$32 -> 0
B46: 9 | C46: Spade Encryption (Pty) Ltd | D46: Tax submission | H46: 1 | I46: =J46*$C$32 -> 0 | J46: =(F46*G46*H46)/$C$32 -> 0
B47: 11 | H47: 1 | I47: =J47*$C$32 -> 0 | J47: =(F47*G47*H47)/$C$32 -> 0
B48: 12 | H48: 1 | I48: =J48*$C$32 -> 0 | J48: =(F48*G48*H48)/$C$32 -> 0
B49: 13 | H49: 1 | I49: =J49*$C$32 -> 0 | J49: =(F49*G49*H49)/$C$32 -> 0
B50: 14 | H50: 1 | I50: =J50*$C$32 -> 0 | J50: =(F50*G50*H50)/$C$32 -> 0
B51: 16 | H51: 1 | I51: =J51*$C$32 -> 0 | J51: =(F51*G51*H51)/$C$32 -> 0
B52: 17 | H52: 1 | I52: =J52*$C$32 -> 0 | J52: =(F52*G52*H52)/$C$32 -> 0
B53: 19 | H53: 1 | I53: =J53*$C$32 -> 0 | J53: =(F53*G53*H53)/$C$32 -> 0
B54: 20 | H54: 1 | I54: =J54*$C$32 -> 0 | J54: =(F54*G54*H54)/$C$32 -> 0
F56: =SUM(F37:F55) -> 24734.36 | I56: =SUM(I35:I55) -> 9893.744 | J56: =SUM(J34:J55) -> 21.986098
E57: Excl VAT | F57: =100/115*F56 -> 21508.139 | H57: Excl VAT | I57: =100/115*I56 -> 8603.2557
C63: Workflow Schedule for | E63: February | J63: 2026
...

Sheet Rudzi Jan - Dec '26
F3: Workflow Scheduling
B8: "A business is a commercial profitable enterprise that runs without you"
C10: Workflow Dashboard
B11: Senior Client Manager In Charge : | G11: Star Bongowongo
B12: Team Name: | G12: Rudzi Mziki
B14: Team Member: | D14: Rudzi | G14: Role: | J14: Accounting Intern
C15: Analysis: | E15: Fees: | G15: Analysis: | K15: Hours:
C16: Annual Fee Budget | E16: =50512*12 -> 606144 | G16: Annual Budgeted Hours | K16: =E16/C32 -> 1346.9867
C17: Scheduled Work and Jobs | E17: =+I64+I108+I177+I247+I317+I387+I457+I527+I597+I667+I737+I807 -> 33101.377 | G17: Scheduled Hours | K17: =+J64+J108+J177+J247+J317+J387+J457+J527+J597+J667+J737+J807 -> 73.558615
C18: Over (Under) Scheduled Work | E18: =E17-E16 -> -573042.62 | G18: Over (Under) Scheduled Work | K18: =K17-K16 -> -1273.4281
B20: Remaining Hours to Fill:
D21: January | E21: =J32 -> 104.78245 | F21: Apr | G21: =+J185 -> 121.6 | H21: July | I21: =+J395 -> 134.4 | J21: Oct | K21: =+J605 -> 147.2
D22: Feb | E22: =+J73 -> 84.058938 | F22: May | G22: =+J255 -> 140.8 | H22: Aug | I22: =J465 -> 134.4 | J22: Nov | K22: =+J675 -> 128
D23: Mar | E23: =+J116 -> 134.4 | F23: June | G23: =+J325 -> 128 | H23: Sept | I23: =+J535 -> 134.4 | J23: Dec | K23: =+J745 -> 128
B25: Total Productivity Hours To Fill : | G25: =SUM(E21:E23)+SUM(G21:G23)+SUM(I21:I23)+SUM(K21:K23) -> 1520.0414
C30: Workflow Schedule for | E30: January | J30: 2026
C31: Charge Rate: | D31: Working Days in Month | F31: KPI % | G31: Hours per Day | H31: Monthly Budgeted Hours | I31: Total Scheduled Fees | J31: Hours Left
C32: 450 | D32: 21 | F32: 0.8 | G32: 8 | H32: =D32*G32*F32 -> 134.4 | I32: =I64 -> 13327.899 | J32: =H32-J64 -> 104.78245
C33: Entity Group \ Job Name | D33: Notes | F33: Estimated Fees for Job | G33: Team Members Job Completion % | H33: Pricing or Efficiency Override | I33: Budgeted WIP | J33: Job Budgeted Hrs | K33: Submission Date to client | L33: Accountants commnent on Due Date
C35: Monthly Recurring Work
C36: Management Accounts:
B37: 1 | C37: CREATIVE VALLEY NURSERY SCHOOL | F37: ='Work Component Split'!F29 -> 2994.59 | G37: ='Work Component Split'!J29 -> 0.27513672 | H37: 1 | I37: =J37*$C$32 -> 823.92167 | J37: =(F37*G37*H37)/$C$32 -> 1.830937
B38: 2 | C38: Rentals Proper team Fourways | F38: ='Work Component Split'!F34 -> 3423.13 | G38: ='Work Component Split'!J34 -> 0.40000005 | H38: 1 | I38: =J38*$C$32 -> 1369.2522 | J38: =(F38*G38*H38)/$C$32 -> 3.0427826
B39: 3 | C39: Mectech Motors | F39: ='Work Component Split'!F36 -> 6389.28 | G39: ='Work Component Split'!K36 -> 0.08296146 | H39: 1 | I39: =J39*$C$32 -> 530.064 | J39: =(F39*G39*H39)/$C$32 -> 1.17792
B40: 4 | C40: R Protections | F40: ='Work Component Split'!F39 -> 8100 | G40: ='Work Component Split'!J39 -> 0.4 | H40: 1 | I40: =J40*$C$32 -> 3240 | J40: =(F40*G40*H40)/$C$32 -> 7.2
B41: 5 | C41: TMM TECH | F41: ='Work Component Split'!F35 -> 3549.91 | G41: ='Work Component Split'!J35 -> 0.40000034 | H41: 1 | I41: =J41*$C$32 -> 1419.9652 | J41: =(F41*G41*H41)/$C$32 -> 3.1554783
B42: 6 | C42: Chemstrat | F42: ='Work Component Split'!F38 -> 14040 | G42: ='Work Component Split'!J38 -> 0.4 | H42: 1 | I42: =J42*$C$32 -> 5616 | J42: =(F42*G42*H42)/$C$32 -> 12.48
B43: 7 | C43: Blue Hills | F43: ='Work Component Split'!F37 -> 3895.65 | G43: ='Work Component Split'!K37 -> 0.084375047 | H43: 1 | I43: =J43*$C$32 -> 328.69565 | J43: =(F43*G43*H43)/$C$32 -> 0.73043478
C45: Once Off work:
B46: 1 | C46: Aquity Innovations NPC | D46: Audit | H46: 1 | I46: =J46*$C$32 -> 0 | J46: =(F46*G46*H46)/$C$32 -> 0
B47: 2 | C47: Bongani Buthelezi | D47: Prepare rental income schedule | H47: 1 | I47: =J47*$C$32 -> 0 | J47: =(F47*G47*H47)/$C$32 -> 0
B48: 4 | C48: Nosipho | D48: Bank statement requisition, cost estimation | H48: 1 | I48: =J48*$C$32 -> 0 | J48: =(F48*G48*H48)/$C$32 -> 0
B49: 5 | C49: DR P Ngwata | D49: due dilligene reports | H49: 1 | I49: =J49*$C$32 -> 0 | J49: =(F49*G49*H49)/$C$32 -> 0
B50: 6 | C50: EmpowerXX | D50: AFS Preparation | H50: 1 | I50: =J50*$C$32 -> 0 | J50: =(F50*G50*H50)/$C$32 -> 0
B51: 7 | C51: Freshly Ground (Pty) Ltd | D51: Management accounts Review | H51: 1 | I51: =J51*$C$32 -> 0 | J51: =(F51*G51*H51)/$C$32 -> 0
B52: 8 | C52: Giant Bee Logistics Pty Ltd | D52: SARS Dispute Resolution | H52: 1 | I52: =J52*$C$32 -> 0 | J52: =(F52*G52*H52)/$C$32 -> 0
B53: 9 | C53: Hylee Choto | D53: 2nd Provisional tax submission , ITR 14 - submission | H53: 1 | I53: =J53*$C$32 -> 0 | J53: =(F53*G53*H53)/$C$32 -> 0
B54: 10 | C54: Jacas Trading (Pty) Ltd | D54: Management accounts | H54: 1 | I54: =J54*$C$32 -> 0 | J54: =(F54*G54*H54)/$C$32 -> 0
B55: 11 | C55: KHANYA CONSORTIUM | D55: (1st) Provisional Tax Submission | H55: 1 | I55: =J55*$C$32 -> 0 | J55: =(F55*G55*H55)/$C$32 -> 0
B56: 12 | C56: Mosuhlamakwe Projects and Trading Enterprise (Pty) Ltd | D56: ITR 14 - submission | H56: 1 | I56: =J56*$C$32 -> 0 | J56: =(F56*G56*H56)/$C$32 -> 0
...

Sheet Katlego Jan - Dec '26
F3: Workflow Scheduling
B8: "A business is a commercial profitable enterprise that runs without you"
C10: Workflow Dashboard
B11: Senior Client Manager In Charge : | G11: Star Bongowongo
B12: Team Name: | G12: Katlego Mamatlepa
B14: Team Member: | D14: Katlego Mamatlepa | G14: Role: | J14: Junior Accountant
C15: Analysis: | E15: Fees: | G15: Analysis: | K15: Hours:
C16: Annual Fee Budget | E16: 408000 | G16: Annual Budgeted Hours | K16: =E16/C32 -> 1165.7143
C17: Scheduled Work and Jobs | E17: =+I64+I110+I179+I249+I319+I389+I459+I529+I599+I669+I739+I809 -> 5239.8489 | G17: Scheduled Hours | K17: =+J64+J110+J179+J249+J319+J389+J459+J529+J599+J669+J739+J809 -> 14.970997
C18: Over (Under) Scheduled Work | E18: =E17-E16 -> -402760.15 | G18: Over (Under) Scheduled Work | K18: =K17-K16 -> -1150.7433
B20: Remaining Hours to Fill:
D21: January | E21: =J32 -> 142.8 | F21: Apr | G21: =+J187 -> 129.2 | H21: July | I21: =+J397 -> 142.8 | J21: Oct | K21: =+J607 -> 156.4
D22: Feb | E22: =+J73 -> 121.029 | F22: May | G22: =+J257 -> 149.6 | H22: Aug | I22: =J467 -> 142.8 | J22: Nov | K22: =+J677 -> 136
D23: Mar | E23: =+J118 -> 142.8 | F23: June | G23: =+J327 -> 136 | H23: Sept | I23: =+J537 -> 142.8 | J23: Dec | K23: =+J747 -> 136
B25: Total Productivity Hours To Fill : | G25: =SUM(E21:E23)+SUM(G21:G23)+SUM(I21:I23)+SUM(K21:K23) -> 1678.229
C30: Workflow Schedule for | E30: January | J30: 2026
C31: Charge Rate: | D31: Working Days in Month | F31: KPI % | G31: Hours per Day | H31: Monthly Budgeted Hours | I31: Total Scheduled Fees | J31: Hours Left
C32: 350 | D32: 21 | F32: 0.85 | G32: 8 | H32: =D32*G32*F32 -> 142.8 | I32: =I64 -> 0 | J32: =H32-J64 -> 142.8
C33: Entity Group \ Job Name | D33: Notes | F33: Estimated Fees for Job | G33: Team Members Job Completion % | H33: Pricing or Efficiency Override | I33: Budgeted WIP | J33: Job Budgeted Hrs | K33: Submission Date to client | L33: Accountants commnent on Due Date
C35: Monthly Recurring Work
C36: Management Accounts:
C45: Once Off Work:
B46: 1 | H46: 1 | I46: =J46*$C$32 -> 0 | J46: =(F46*G46*H46)/$C$32 -> 0
B47: 2 | H47: 1 | I47: =J47*$C$32 -> 0 | J47: =(F47*G47*H47)/$C$32 -> 0
B48: 4 | H48: 1 | I48: =J48*$C$32 -> 0 | J48: =(F48*G48*H48)/$C$32 -> 0
B49: 5 | H49: 1 | I49: =J49*$C$32 -> 0 | J49: =(F49*G49*H49)/$C$32 -> 0
B50: 6 | H50: 1 | I50: =J50*$C$32 -> 0 | J50: =(F50*G50*H50)/$C$32 -> 0
B51: 7 | H51: 1 | I51: =J51*$C$32 -> 0 | J51: =(F51*G51*H51)/$C$32 -> 0
B52: 8 | H52: 1 | I52: =J52*$C$32 -> 0 | J52: =(F52*G52*H52)/$C$32 -> 0
B53: 9 | H53: 1 | I53: =J53*$C$32 -> 0 | J53: =(F53*G53*H53)/$C$32 -> 0
B54: 10 | H54: 1 | I54: =J54*$C$32 -> 0 | J54: =(F54*G54*H54)/$C$32 -> 0
B55: 11 | H55: 1 | I55: =J55*$C$32 -> 0 | J55: =(F55*G55*H55)/$C$32 -> 0
B56: 12 | H56: 1 | I56: =J56*$C$32 -> 0 | J56: =(F56*G56*H56)/$C$32 -> 0
B57: 13 | H57: 1 | I57: =J57*$C$32 -> 0 | J57: =(F57*G57*H57)/$C$32 -> 0
... B62: 20 | H62: 1 | I62: =J62*$C$32 -> 0 | J62: =(F62*G62*H62)/$C$32 -> 0
F64: =SUM(F37:F63) -> 0 | I64: =SUM(I35:I63) -> 0 | J64: =SUM(J34:J63) -> 0
E65: Excl VAT | F65: =100/115*F64 -> 0 | H65: Excl VAT | I65: =100/115*I64 -> 0
C71: Workflow Schedule for | E71: February | J71: 2026
C72: Charge Rate: | D72: Working Days in Month | F72: KPI % | G72: Hours per Day | H72: Monthly Budgeted Hours | I72: Total Scheduled Fees | J72: Hours Left
C73: =C32 -> 350 | D73: 20 | F73: =F32 -> 0.85 | G73: =G32 -> 8 | H73: =D73*G73*F73 -> 136 | I73: =I110 -> 5239.8489 | J73: =H73-J110 -> 121.029
...

Sheet Bruce Jan - Dec '26
F3: Workflow Scheduling
B8: "A business is a commercial profitable enterprise that runs without you"
C10: Workflow Dashboard
B11: Senior Client Manager In Charge : | G11: Star Bongowongo
B12: Team Name: | G12: Bruce Saurombe
B14: Team Member: | D14: Bruce | G14: Role: | J14: Accountant
C15: Analysis: | E15: Fees: | G15: Analysis: | K15: Hours:
C16: Annual Fee Budget | E16: =54720*12 -> 656640 | G16: Annual Budgeted Hours | K16: =E16/C32 -> 1459.2
C17: Scheduled Work and Jobs | E17: =+I65+I110+I179+I249+I319+I389+I459+I529+I599+I669+I739+I809 -> #VALUE! | G17: Scheduled Hours | K17: =+J65+J110+J179+J249+J319+J389+J459+J529+J599+J669+J739+J809 -> #VALUE!
C18: Over (Under) Scheduled Work | E18: =E17-E16 -> #VALUE! | G18: Over (Under) Scheduled Work | K18: =K17-K16 -> #VALUE!
B20: Remaining Hours to Fill:
D21: January | E21: =J32 -> #VALUE! | F21: Apr | G21: =+J187 -> 121.6 | H21: July | I21: =+J397 -> 134.4 | J21: Oct | K21: =+J607 -> 147.2
D22: Feb | E22: =+J74 -> 18.998129 | F22: May | G22: =+J257 -> 140.8 | H22: Aug | I22: =J467 -> 134.4 | J22: Nov | K22: =+J677 -> 128
D23: Mar | E23: =+J118 -> 134.4 | F23: June | G23: =+J327 -> 128 | H23: Sept | I23: =+J537 -> 134.4 | J23: Dec | K23: =+J747 -> 128
B25: Total Productivity Hours To Fill : | G25: =SUM(E21:E23)+SUM(G21:G23)+SUM(I21:I23)+SUM(K21:K23) -> #VALUE!
C30: Workflow Schedule for | E30: January | J30: 2026
C31: Charge Rate: | D31: Working Days in Month | F31: KPI % | G31: Hours per Day | H31: Monthly Budgeted Hours | I31: Total Scheduled Fees | J31: Hours Left
C32: 450 | D32: 21 | F32: 0.8 | G32: 8 | H32: =D32*G32*F32 -> 134.4 | I32: =I65 -> #VALUE! | J32: =H32-J65 -> #VALUE!
C33: Entity Group \ Job Name | D33: Notes | F33: Estimated Fees for Job | G33: Team Members Job Completion % | H33: Pricing or Efficiency Override | I33: Budgeted WIP | J33: Job Budgeted Hrs | K33: Submission Date to client | L33: Accountants commnent on Due Date
C35: Monthly Recurring Work
C36: Management Accounts:
B37: 1 | C37: Vera Step | F37: 2943 | G37: 0.4 | H37: 1 | I37: =J37*$C$32 -> 1177.2 | J37: =(F37*G37*H37)/$C$32 -> 2.616
B38: 2 | C38: Moja Legal Consulting and Investment (Pty) Ltd | F38: 2028.52 | G38: 0.4 | H38: 1 | I38: =J38*$C$32 -> 811.408 | J38: =(F38*G38*H38)/$C$32 -> 1.8031289
B39: 3 | C39: Bona By Wenzy | F39: 1890 | G39: 0.4 | H39: 1 | I39: =J39*$C$32 -> 756 | J39: =(F39*G39*H39)/$C$32 -> 1.68
B40: 4 | C40: Mawela Simpson | F40: 3888 | G40: 0.4 | H40: 1 | I40: =J40*$C$32 -> 1555.2 | J40: =(F40*G40*H40)/$C$32 -> 3.456
B41: 5 | C41: MGI Global | F41: 2916 | G41: 0.4 | H41: 1 | I41: =J41*$C$32 -> 1166.4 | J41: =(F41*G41*H41)/$C$32 -> 2.592
B42: 6 | C42: Plush Spaces | F42: 2303.5043 | G42: 0.33357871 | H42: 0 | I42: =J42*$C$32 -> 0 | J42: =(F42*G42*H42)/$C$32 -> 0
B43: 7 | C43: Swiiff | F43: 2916 | G43: 0.4 | H43: 1 | I43: =J43*$C$32 -> 1166.4 | J43: =(F43*G43*H43)/$C$32 -> 2.592
B44: 8 | C44: Fitness Reenvisioned | F44: 1572.1 | G44: 0.40000111 | H44: 1 | I44: =J44*$C$32 -> 628.84174 | J44: =(F44*G44*H44)/$C$32 -> 1.3974261
B45: 9 | C45: Susbtream | F45: 5352.48 | G45: 0.4 | H45: 1 | I45: =J45*$C$32 -> 2140.992 | J45: =(F45*G45*H45)/$C$32 -> 4.75776
C48: Once Off work:
B49: 1 | C49: Aquity | F49: R | G49: 0.4 | H49: 1 | I49: =J49*$C$32 -> #VALUE! | J49: =(F49*G49*H49)/$C$32 -> #VALUE!
B50: 2 | F50: 9200 | G50: 0.9 | H50: 1 | I50: =J50*$C$32 -> 8280 | J50: =(F50*G50*H50)/$C$32 -> 18.4
B51: 6 | H51: 1 | I51: =J51*$C$32 -> 0 | J51: =(F51*G51*H51)/$C$32 -> 0
B52: 7 | H52: 1 | I52: =J52*$C$32 -> 0 | J52: =(F52*G52*H52)/$C$32 -> 0
B53: 8 | H53: 1 | I53: =J53*$C$32 -> 0 | J53: =(F53*G53*H53)/$C$32 -> 0
B54: 9 | H54: 1 | I54: =J54*$C$32 -> 0 | J54: =(F54*G54*H54)/$C$32 -> 0
B55: 10 | H55: 1 | I55: =J55*$C$32 -> 0 | J55: =(F55*G55*H55)/$C$32 -> 0
B56: 11 | H56: 1 | I56: =J56*$C$32 -> 0 | J56: =(F56*G56*H56)/$C$32 -> 0
B57: 12 | H57: 1 | I57: =J57*$C$32 -> 0 | J57: =(F57*G57*H57)/$C$32 -> 0
...

Sheet Christine Jan - Dec '26
F3: Workflow Scheduling
B8: "A business is a commercial profitable enterprise that runs without you"
C10: Workflow Dashboard
B11: Senior Client Manager In Charge : | G11: Star Bongowongo
B12: Team Name: | G12: Christine Mashava
B14: Team Member: | D14: Christine | G14: Role: | J14: Junior Accountant
C15: Analysis: | E15: Fees: | G15: Analysis: | K15: Hours:
C16: Annual Fee Budget | E16: =50512*12 -> 606144 | G16: Annual Budgeted Hours | K16: =E16/C32 -> 1346.9867
C17: Scheduled Work and Jobs | E17: =+I88+I154+I223+I293+I363+I433+I503+I573+I643+I713+I783+I853 -> 89730.791 | G17: Scheduled Hours | K17: =+J88+J154+J223+J293+J363+J433+J503+J573+J643+J713+J783+J853 -> 199.40176
C18: Over (Under) Scheduled Work | E18: =E17-E16 -> -516413.21 | G18: Over (Under) Scheduled Work | K18: =K17-K16 -> -1147.5849
B20: Remaining Hours to Fill:
D21: January | E21: =J32 -> 49.57851 | F21: Apr | G21: =+J231 -> 121.6 | H21: July | I21: =+J441 -> 134.4 | J21: Oct | K21: =+J651 -> 147.2
D22: Feb | E22: =+J97 -> 13.419732 | F22: May | G22: =+J301 -> 140.8 | H22: Aug | I22: =J511 -> 134.4 | J22: Nov | K22: =+J721 -> 128
D23: Mar | E23: =+J162 -> 134.4 | F23: June | G23: =+J371 -> 128 | H23: Sept | I23: =+J581 -> 134.4 | J23: Dec | K23: =+J791 -> 128
B25: Total Productivity Hours To Fill : | G25: =SUM(E21:E23)+SUM(G21:G23)+SUM(I21:I23)+SUM(K21:K23) -> 1394.1982
C30: Workflow Schedule for | E30: January | J30: 2026
C31: Charge Rate: | D31: Working Days in Month | F31: KPI % | G31: Hours per Day | H31: Monthly Budgeted Hours | I31: Total Scheduled Fees | J31: Hours Left
C32: 450 | D32: 21 | F32: 0.8 | G32: 8 | H32: =D32*G32*F32 -> 134.4 | I32: =I88 -> 38169.671 | J32: =H32-J88 -> 49.57851
C33: Entity Group \ Job Name | D33: Notes | F33: Estimated Fees for Job | G33: Team Members Job Completion % | H33: Pricing or Efficiency Override | I33: Budgeted WIP | J33: Job Budgeted Hrs | K33: Submission Date to client | L33: Accountants commnent on Due Date
C35: Monthly Recurring Work
C36: Management Accounts:
C40: Payroll:
B41: 1 | C41: Maxopani Holdings | F41: 26548.8 | G41: 0.3 | H41: 1 | I41: =J41*$C$32 -> 7964.64 | J41: =(F41*G41*H41)/$C$32 -> 17.6992
B42: =B41+1 -> 2 | C42: Makhubela Incorporated | F42: 2351.77 | G42: 0.21 | H42: 1 | I42: =J42*$C$32 -> 493.8717 | J42: =(F42*G42*H42)/$C$32 -> 1.0974927
B43: =B42+1 -> 3 | C43: Destiny Finance (Pty) Ltd | F43: 10198.79 | G43: 0.35 | H43: 1 | I43: =J43*$C$32 -> 3569.5765 | J43: =(F43*G43*H43)/$C$32 -> 7.9323922
B44: =B43+1 -> 4 | C44: DR WW NGWATA PRACTICE INC | F44: 3649.02 | G44: 0.13 | H44: 1 | I44: =J44*$C$32 -> 474.3726 | J44: =(F44*G44*H44)/$C$32 -> 1.0541613
B45: =B44+1 -> 5 | C45: Bixa Consulting | F45: 3294.5 | G45: 0.15 | H45: 1 | I45: =J45*$C$32 -> 494.175 | J45: =(F45*G45*H45)/$C$32 -> 1.0981667
B46: =B45+1 -> 6 | C46: Giant Bee Logistics Pty Ltd | F46: 6662.57 | G46: 0.19 | H46: 1 | I46: =J46*$C$32 -> 1265.8883 | J46: =(F46*G46*H46)/$C$32 -> 2.8130851
B47: =B46+1 -> 7 | C47: Astra Matellite | F47: ='Work Component Split'!F27 -> 5328.2935 | G47: 0 | H47: 1 | I47: =J47*$C$32 -> 0 | J47: =(F47*G47*H47)/$C$32 -> 0
B48: =B47+1 -> 8 | C48: CREATIVE VALLEY NURSERY SCHOOL | F48: 3443.7748 | G48: 0.31 | H48: 1 | I48: =J48*$C$32 -> 1067.5702 | J48: =(F48*G48*H48)/$C$32 -> 2.3723782
B49: =B48+1 -> 9 | C49: Depesh Cara | F49: 540 | G49: 1 | H49: 1 | I49: =J49*$C$32 -> 540 | J49: =(F49*G49*H49)/$C$32 -> 1.2
B50: =B49+1 -> 10 | C50: Dr A.S Bajomo | F50: 4639.852 | G50: 0.12 | H50: 1 | I50: =J50*$C$32 -> 556.78224 | J50: =(F50*G50*H50)/$C$32 -> 1.2372939
B51: =B50+1 -> 11 | C51: Mectech Motors | F51: 7347.672 | G51: 0.17 | H51: 1 | I51: =J51*$C$32 -> 1249.1042 | J51: =(F51*G51*H51)/$C$32 -> 2.7757872
B52: =B51+1 -> 12 | C52: Blue Hill | F52: 4480 | G52: 0.16 | H52: 1 | I52: =J52*$C$32 -> 716.8 | J52: =(F52*G52*H52)/$C$32 -> 1.5928889
B53: =B52+1 -> 13 | C53: Natasha Mohunlal | F53: 2613.6 | G53: 0.19 | H53: 1 | I53: =J53*$C$32 -> 496.584 | J53: =(F53*G53*H53)/$C$32 -> 1.10352
B54: =B53+1 -> 14 | C54: MMFS | F54: 4807 | G54: 0.1 | H54: 1 | I54: =J54*$C$32 -> 480.7 | J54: =(F54*G54*H54)/$C$32 -> 1.0682222
B55: =B54+1 -> 15 | C55: CN Freight | F55: 4708.216 | G55: 0.12 | H55: 1 | I55: =J55*$C$32 -> 564.98592 | J55: =(F55*G55*H55)/$C$32 -> 1.2555243
B56: =B55+1 -> 16 | C56: Promote Balance | F56: 496.8 | G56: 1 | H56: 1 | I56: =J56*$C$32 -> 496.8 | J56: =(F56*G56*H56)/$C$32 -> 1.104
B57: =B56+1 -> 17 | C57: Bophelong | F57: 2918.7 | G57: 1 | H57: 1 | I57: =J57*$C$32 -> 2918.7 | J57: =(F57*G57*H57)/$C$32 -> 6.486
B58: =B57+1 -> 18 | C58: Makhubela Incorporated | F58: 500 | G58: 1 | H58: 1 | I58: =J58*$C$32 -> 500 | J58: =(F58*G58*H58)/$C$32 -> 1.1111111
...

Sheet Lesego Jan - Dec '26
F3: Workflow Scheduling
B8: "A business is a commercial profitable enterprise that runs without you"
C10: Workflow Dashboard
B11: Senior Client Manager In Charge : | G11: Rudzi Mziki
B12: Team Name: | G12: Lesego Moncho
B14: Team Member: | D14: Lesego | G14: Role: | J14: Accounting Intern
C15: Analysis: | E15: Fees: | G15: Analysis: | K15: Hours:
C16: Annual Fee Budget | E16: =34000*12 -> 408000 | G16: Annual Budgeted Hours | K16: =E16/C32 -> 1632
C17: Scheduled Work and Jobs | E17: =+I70+I139+I208+I278+I348+I418+I488+I558+I628+I698+I768+I838 -> 14899.513 | G17: Scheduled Hours | K17: =+J70+J139+J208+J278+J348+J418+J488+J558+J628+J698+J768+J838 -> 59.598051
C18: Over (Under) Scheduled Work | E18: =E17-E16 -> -393100.49 | G18: Over (Under) Scheduled Work | K18: =K17-K16 -> -1572.4019
B20: Remaining Hours to Fill:
D21: January | E21: =J32 -> 83.201949 | F21: Apr | G21: =+J216 -> 129.2 | H21: July | I21: =+J426 -> 142.8 | J21: Oct | K21: =+J636 -> 156.4
D22: Feb | E22: =+J79 -> 136 | F22: May | G22: =+J286 -> 149.6 | H22: Aug | I22: =J496 -> 142.8 | J22: Nov | K22: =+J706 -> 136
D23: Mar | E23: =+J147 -> 142.8 | F23: June | G23: =+J356 -> 136 | H23: Sept | I23: =+J566 -> 142.8 | J23: Dec | K23: =+J776 -> 136
B25: Total Productivity Hours To Fill : | G25: =SUM(E21:E23)+SUM(G21:G23)+SUM(I21:I23)+SUM(K21:K23) -> 1633.6019
C30: Workflow Schedule for | E30: January | J30: 2026
C31: Charge Rate: | D31: Working Days in Month | F31: KPI % | G31: Hours per Day | H31: Monthly Budgeted Hours | I31: Total Scheduled Fees | J31: Hours Left
C32: 250 | D32: 21 | F32: 0.85 | G32: 8 | H32: =D32*G32*F32 -> 142.8 | I32: =I70 -> 14899.513 | J32: =H32-J70 -> 83.201949
C33: Entity Group \ Job Name | D33: Notes | F33: Estimated Fees for Job | G33: Team Members Job Completion % | H33: Pricing or Efficiency Override | I33: Budgeted WIP | J33: Job Budgeted Hrs | K33: Submission Date to client | L33: Accountants commnent on Due Date
C35: Monthly Recurring Work
C36: Management Accounts:
A37: ='Rudzi Jan - Dec ''26'!A37 -> 0 | B37: 1 | C37: Advocate Maputla | F37: ='Work Component Split'!F28 -> 25181.84 | G37: ='Work Component Split'!I28 -> 0.50000007 | H37: 1 | I37: =J37*$C$32 -> 12590.922 | J37: =(F37*G37*H37)/$C$32 -> 50.363687
B38: 2 | C38: Maxopani Holdings | F38: ='Work Component Split'!F10 -> 23085.91 | G38: 0.1 | H38: 1 | I38: =J38*$C$32 -> 2308.591 | J38: =(F38*G38*H38)/$C$32 -> 9.234364
C51: Once Off work:
B52: 1 | H52: 1 | I52: =J52*$C$32 -> 0 | J52: =(F52*G52*H52)/$C$32 -> 0
B53: 2 | H53: 1 | I53: =J53*$C$32 -> 0 | J53: =(F53*G53*H53)/$C$32 -> 0
B54: 4 | H54: 1 | I54: =J54*$C$32 -> 0 | J54: =(F54*G54*H54)/$C$32 -> 0
B55: 5 | H55: 1 | I55: =J55*$C$32 -> 0 | J55: =(F55*G55*H55)/$C$32 -> 0
B56: 6 | H56: 1 | I56: =J56*$C$32 -> 0 | J56: =(F56*G56*H56)/$C$32 -> 0
B57: 7 | H57: 1 | I57: =J57*$C$32 -> 0 | J57: =(F57*G57*H57)/$C$32 -> 0
B58: 8 | H58: 1 | I58: =J58*$C$32 -> 0 | J58: =(F58*G58*H58)/$C$32 -> 0
B59: 9 | H59: 1 | I59: =J59*$C$32 -> 0 | J59: =(F59*G59*H59)/$C$32 -> 0
B60: 10 | H60: 1 | I60: =J60*$C$32 -> 0 | J60: =(F60*G60*H60)/$C$32 -> 0
B61: 11 | H61: 1 | I61: =J61*$C$32 -> 0 | J61: =(F61*G61*H61)/$C$32 -> 0
B62: 12 | H62: 1 | I62: =J62*$C$32 -> 0 | J62: =(F62*G62*H62)/$C$32 -> 0
B63: 13 | H63: 1 | I63: =J63*$C$32 -> 0 | J63: =(F63*G63*H63)/$C$32 -> 0
... B68: 20 | H68: 1 | I68: =J68*$C$32 -> 0 | J68: =(F68*G68*H68)/$C$32 -> 0
F70: =SUM(F37:F69) -> 48267.75 | I70: =SUM(I35:I69) -> 14899.513 | J70: =SUM(J34:J69) -> 59.598051
E71: Excl VAT | F71: =100/115*F70 -> 41971.957 | H71: Excl VAT | I71: =100/115*I70 -> 12956.098
C77: Workflow Schedule for | E77: February | J77: 2026
...

Sheet Simelinkosi Jan - Dec '26
F3: Workflow Scheduling
B8: "A business is a commercial profitable enterprise that runs without you"
C10: Workflow Dashboard
B11: Senior Client Manager In Charge : | G11: Bruce Saurombe
B12: Team Name: | G12: Simelinkosi Kariga
B14: Team Member: | D14: Simelinkosi | G14: Role: | J14: Bookkeeper
C15: Analysis: | E15: Fees: | G15: Analysis: | K15: Hours:
C16: Annual Fee Budget | E16: =50512*12 -> 606144 | G16: Annual Budgeted Hours | K16: =E16/C32 -> 2424.576
C17: Scheduled Work and Jobs | E17: =+I71+I140+I209+I279+I349+I419+I489+I559+I629+I699+I769+I839 -> 17076.655 | G17: Scheduled Hours | K17: =+J71+J140+J209+J279+J349+J419+J489+J559+J629+J699+J769+J839 -> 68.306619
C18: Over (Under) Scheduled Work | E18: =E17-E16 -> -589067.35 | G18: Over (Under) Scheduled Work | K18: =K17-K16 -> -2356.2694
B20: Remaining Hours to Fill:
D21: January | E21: =J32 -> 57.693381 | F21: Apr | G21: =+J217 -> 114 | H21: July | I21: =+J427 -> 126 | J21: Oct | K21: =+J637 -> 138
D22: Feb | E22: =+J80 -> 120 | F22: May | G22: =+J287 -> 132 | H22: Aug | I22: =J497 -> 126 | J22: Nov | K22: =+J707 -> 120
D23: Mar | E23: =+J148 -> 126 | F23: June | G23: =+J357 -> 120 | H23: Sept | I23: =+J567 -> 126 | J23: Dec | K23: =+J777 -> 120
B25: Total Productivity Hours To Fill : | G25: =SUM(E21:E23)+SUM(G21:G23)+SUM(I21:I23)+SUM(K21:K23) -> 1425.6934
C30: Workflow Schedule for | E30: January | J30: 2026
C31: Charge Rate: | D31: Working Days in Month | F31: KPI % | G31: Hours per Day | H31: Monthly Budgeted Hours | I31: Total Scheduled Fees | J31: Hours Left
C32: 250 | D32: 21 | F32: 0.75 | G32: 8 | H32: =D32*G32*F32 -> 126 | I32: =I71 -> 17076.655 | J32: =H32-J71 -> 57.693381
C33: Entity Group \ Job Name | D33: Notes | F33: Estimated Fees for Job | G33: Team Members Job Completion % | H33: Pricing or Efficiency Override | I33: Budgeted WIP | J33: Job Budgeted Hrs | K33: Submission Date to client | L33: Accountants commnent on Due Date
C35: Monthly Recurring Work
C36: Management Accounts:
B37: 1 | C37: Fitness Reenvisioned | F37: ='Work Component Split'!F40 -> 1572.1 | G37: ='Work Component Split'!I40 -> 0.50000138 | H37: 1 | I37: =J37*$C$32 -> 786.05217 | J37: =(F37*G37*H37)/$C$32 -> 3.1442087
B38: 2 | C38: Luk Capital | F38: ='Work Component Split'!F41 -> 2596.51 | G38: ='Work Component Split'!I41 -> 0.49999958 | H38: 1 | I38: =J38*$C$32 -> 1298.2539 | J38: =(F38*G38*H38)/$C$32 -> 5.1930157
B39: 3 | C39: Moja Legal Consulting and Investment (Pty) Ltd | F39: ='Work Component Split'!F42 -> 2028.52 | G39: ='Work Component Split'!I42 -> 0.50000043 | H39: 1 | I39: =J39*$C$32 -> 1014.2609 | J39: =(F39*G39*H39)/$C$32 -> 4.0570435
B40: 4 | C40: Vera Step | F40: ='Work Component Split'!F43 -> 2943 | G40: ='Work Component Split'!I43 -> 0.5 | H40: 1 | I40: =J40*$C$32 -> 1471.5 | J40: =(F40*G40*H40)/$C$32 -> 5.886
B41: 5 | C41: Natasha Mohunlal | F41: ='Work Component Split'!F44 -> 2272.7 | G41: ='Work Component Split'!I44 -> 0.4049579 | H41: 1 | I41: =J41*$C$32 -> 920.34783 | J41: =(F41*G41*H41)/$C$32 -> 3.6813913
B42: 6 | C42: Swiiff | F42: ='Work Component Split'!F45 -> 2916 | G42: ='Work Component Split'!I45 -> 0.5 | H42: 1 | I42: =J42*$C$32 -> 1458 | J42: =(F42*G42*H42)/$C$32 -> 5.832
A43: every 6 months | B43: 7 | C43: Mawela Simpson | F43: ='Work Component Split'!F46 -> 3888 | G43: ='Work Component Split'!I46 -> 0.5 | H43: 1 | I43: =J43*$C$32 -> 1944 | J43: =(F43*G43*H43)/$C$32 -> 7.776
A44: every 2 months | B44: 8 | C44: MGI Global | F44: ='Work Component Split'!F47 -> 2916 | G44: ='Work Component Split'!I47 -> 0.5 | H44: 1 | I44: =J44*$C$32 -> 1458 | J44: =(F44*G44*H44)/$C$32 -> 5.832
B45: 9 | C45: MMFS | F45: ='Work Component Split'!F48 -> 4180 | G45: ='Work Component Split'!I48 -> 0.45215311 | H45: 1 | I45: =J45*$C$32 -> 1890 | J45: =(F45*G45*H45)/$C$32 -> 7.56
B46: 10 | C46: Bona By Wenzy | F46: ='Work Component Split'!F49 -> 1890 | G46: ='Work Component Split'!I49 -> 0.5 | H46: 1 | I46: =J46*$C$32 -> 945 | J46: =(F46*G46*H46)/$C$32 -> 3.78
B47: 11 | C47: Recovery Advisors | F47: ='Work Component Split'!F50 -> 2430 | G47: ='Work Component Split'!I50 -> 0.5 | H47: 1 | I47: =J47*$C$32 -> 1215 | J47: =(F47*G47*H47)/$C$32 -> 4.86
B48: 12 | C48: Subtream | F48: ='Work Component Split'!F51 -> 5352.48 | G48: ='Work Component Split'!I51 -> 0.5 | H48: 1 | I48: =J48*$C$32 -> 2676.24 | J48: =(F48*G48*H48)/$C$32 -> 10.70496
B49: 13 | C49: Plush Spaces | F49: ='Work Component Split'!F52 -> 2303.5043 | G49: 0 | H49: 1 | I49: =J49*$C$32 -> 0 | J49: =(F49*G49*H49)/$C$32 -> 0
C52: Once Off work:
B53: 1 | H53: 1 | I53: =J53*$C$32 -> 0 | J53: =(F53*G53*H53)/$C$32 -> 0
B54: 2 | H54: 1 | I54: =J54*$C$32 -> 0 | J54: =(F54*G54*H54)/$C$32 -> 0
B55: 4 | H55: 1 | I55: =J55*$C$32 -> 0 | J55: =(F55*G55*H55)/$C$32 -> 0
B56: 5 | H56: 1 | I56: =J56*$C$32 -> 0 | J56: =(F56*G56*H56)/$C$32 -> 0
B57: 6 | H57: 1 | I57: =J57*$C$32 -> 0 | J57: =(F57*G57*H57)/$C$32 -> 0
...

Sheet Mavis Jan - Dec '26
F3: Workflow Scheduling
B8: "A business is a commercial profitable enterprise that runs without you"
C10: Workflow Dashboard
B11: Senior Client Manager In Charge : | G11: Kenneth Mashava
B12: Team Name: | G12: Mavis Bincent
B14: Team Member: | D14: Mavis | G14: Role: | J14: Bookkeeper
C15: Analysis: | E15: Fees: | G15: Analysis: | K15: Hours:
C16: Annual Fee Budget | E16: =50512*12 -> 606144 | G16: Annual Budgeted Hours | K16: =E16/C32 -> 2424.576
C17: Scheduled Work and Jobs | E17: =+I70+I139+I208+I278+I348+I418+I488+I558+I628+I698+I768+I838 -> 14675.77 | G17: Scheduled Hours | K17: =+J70+J139+J208+J278+J348+J418+J488+J558+J628+J698+J768+J838 -> 58.703078
C18: Over (Under) Scheduled Work | E18: =E17-E16 -> -591468.23 | G18: Over (Under) Scheduled Work | K18: =K17-K16 -> -2365.8729
B20: Remaining Hours to Fill:
D21: January | E21: =J32 -> 67.296922 | F21: Apr | G21: =+J216 -> 114 | H21: July | I21: =+J426 -> 126 | J21: Oct | K21: =+J636 -> 138
D22: Feb | E22: =+J79 -> 120 | F22: May | G22: =+J286 -> 132 | H22: Aug | I22: =J496 -> 126 | J22: Nov | K22: =+J706 -> 120
D23: Mar | E23: =+J147 -> 126 | F23: June | G23: =+J356 -> 120 | H23: Sept | I23: =+J566 -> 126 | J23: Dec | K23: =+J776 -> 120
B25: Total Productivity Hours To Fill : | G25: =SUM(E21:E23)+SUM(G21:G23)+SUM(I21:I23)+SUM(K21:K23) -> 1435.2969
C30: Workflow Schedule for | E30: January | J30: 2026
C31: Charge Rate: | D31: Working Days in Month | F31: KPI % | G31: Hours per Day | H31: Monthly Budgeted Hours | I31: Total Scheduled Fees | J31: Hours Left
C32: 250 | D32: 21 | F32: 0.75 | G32: 8 | H32: =D32*G32*F32 -> 126 | I32: =I70 -> 14675.77 | J32: =H32-J70 -> 67.296922
C33: Entity Group \ Job Name | D33: Notes | F33: Estimated Fees for Job | G33: Team Members Job Completion % | H33: Pricing or Efficiency Override | I33: Budgeted WIP | J33: Job Budgeted Hrs | K33: Submission Date to client | L33: Accountants commnent on Due Date
C35: Monthly Recurring Work
C36: Management Accounts:
B37: 1 | C37: Innovateher | F37: ='Work Component Split'!F12 -> 24734.36 | G37: ='Work Component Split'!I12 -> 0.49999994 | H37: 1 | I37: =J37*$C$32 -> 12367.179 | J37: =(F37*G37*H37)/$C$32 -> 49.468714
B38: 2 | C38: Maxopani Holdings | F38: ='Work Component Split'!F10 -> 23085.91 | G38: 0.1 | H38: 1 | I38: =J38*$C$32 -> 2308.591 | J38: =(F38*G38*H38)/$C$32 -> 9.234364
C51: Once Off work:
B52: 1 | H52: 1 | I52: =J52*$C$32 -> 0 | J52: =(F52*G52*H52)/$C$32 -> 0
B53: 2 | H53: 1 | I53: =J53*$C$32 -> 0 | J53: =(F53*G53*H53)/$C$32 -> 0
B54: 4 | H54: 1 | I54: =J54*$C$32 -> 0 | J54: =(F54*G54*H54)/$C$32 -> 0
B55: 5 | H55: 1 | I55: =J55*$C$32 -> 0 | J55: =(F55*G55*H55)/$C$32 -> 0
B56: 6 | H56: 1 | I56: =J56*$C$32 -> 0 | J56: =(F56*G56*H56)/$C$32 -> 0
B57: 7 | H57: 1 | I57: =J57*$C$32 -> 0 | J57: =(F57*G57*H57)/$C$32 -> 0
B58: 8 | H58: 1 | I58: =J58*$C$32 -> 0 | J58: =(F58*G58*H58)/$C$32 -> 0
B59: 9 | H59: 1 | I59: =J59*$C$32 -> 0 | J59: =(F59*G59*H59)/$C$32 -> 0
B60: 10 | H60: 1 | I60: =J60*$C$32 -> 0 | J60: =(F60*G60*H60)/$C$32 -> 0
B61: 11 | H61: 1 | I61: =J61*$C$32 -> 0 | J61: =(F61*G61*H61)/$C$32 -> 0
B62: 12 | H62: 1 | I62: =J62*$C$32 -> 0 | J62: =(F62*G62*H62)/$C$32 -> 0
B63: 13 | H63: 1 | I63: =J63*$C$32 -> 0 | J63: =(F63*G63*H63)/$C$32 -> 0
... B68: 20 | H68: 1 | I68: =J68*$C$32 -> 0 | J68: =(F68*G68*H68)/$C$32 -> 0
F70: =SUM(F37:F69) -> 47820.27 | I70: =SUM(I35:I69) -> 14675.77 | J70: =SUM(J34:J69) -> 58.703078
E71: Excl VAT | F71: =100/115*F70 -> 41582.843 | H71: Excl VAT | I71: =100/115*I70 -> 12761.539
C77: Workflow Schedule for | E77: February | J77: 2026
...
